Workbook
Name application_status_current: Lookup_Lists!$C$5:$C$12
Name bond_issuer_type: Lookup_Lists!$I$5:$I$7
Name construction_type: Lookup_Lists!$E$5:$E$9
Name predicted_advance_flag: Lookup_Lists!$O$5:$O$7
Name predicted_next_path: Lookup_Lists!$M$5:$M$11
Name predicted_next_status: Lookup_Lists!$K$5:$K$12
Name target_population: Lookup_Lists!$G$5:$G$8
Name yes_no: Lookup_Lists!$A$5:$A$6

Sheet Read_Me
A1: Texas 2025 4% + Tax-Exempt Bond Simulator Template
A3: Purpose | B3: This workbook is a starter input template for a Texas 2025 4% + tax-exempt bond rules engine.
A4: How to use | B4: 1) Paste the latest status-log universe into Applicant_List. 2) Fill the orange/purple manual QAP fields. 3) Enter one test project in Hypothetical_Project. 4) Have the Python engine write results to Rules_Output or the engine output columns.
A5: Color key | B5: Blue font = manual input. Black font = formulas / derived values. Gray fill = derived logic. Light red fill = engine outputs. Orange/purple sections = manual QAP and site rule inputs.
A6: Required fields | B6: Columns marked Req in Lookup_Lists should be completed before running the simulator.
A7: Derived flags | B7: all_manual_boxes_checked_flag and project_ready_now_flag are formula-driven helper fields. They are intended as starter logic and can be refined as the Texas engine matures.
A8: Scope note | B8: This template is for a Texas pipeline/rules engine, not a California-style score-and-award allocator.
A10: Key tabs
A11: Applicant_List | B11: Main status-log universe plus added QAP/manual fields.
A12: Hypothetical_Project | B12: Single-row test project with same schema as Applicant_List.
A13: Rules_Output | B13: Output area for the simulator/decision engine.
A14: Lookup_Lists | B14: Dropdown values plus full field dictionary.
A16: New in this version | B16: Adds a queue-based funding allocation layer: projects are screened by the existing rules engine, sorted by reservation-date priority, and funded until the manual capacity assumption is exhausted.

Sheet Applicant_List
A1: Texas 2025 4% + Tax-Exempt Bond Simulator - 2026-02-10 mapped status log
A2: Identity & Snapshot | K2: Current Public Process | R2: Project Characteristics | X2: Bond & Credit Structure | AI2: Manual QAP Thresholds | BB2: Site / Deconcentration | BJ2: Path Selection | BO2: Queue / Priority | BU2: Engine Outputs | CC2: Notes & Contacts
A3: snapshot_date | B3: application_source_log | C3: tdhca_number | D3: previous_tdhca_number | E3: development_name | F3: development_city | G3: development_county | H3: development_region | I3: development_address | J3: zip_code | K3: full_application_submission_date | L3: application_status_current | M3: board_meeting_date_current | N3: determination_notice_issuance_date_current | O3: bond_reservation_date_current | P3: bond_expiration_date_current | Q3: closed_date_current | R3: construction_type | S3: target_population | T3: total_units | U3: total_low_income_units | V3: scattered_site_flag | W3: existing_residential_development_flag | X3: bond_issuer | Y3: bond_issuer_type | Z3: bond_reservation_amount_requested | AA3: bond_amount_recommended | AB3: requested_htc_amount | AC3: recommended_htc_amount | AD3: requested_state_tax_credit_amount | AE3: recommended_state_tax_credit_amount | AF3: direct_loan_request_flag | AG3: property_tax_exemption_flag | AH3: pfc_structure_flag | AI3: site_control_valid_flag | AJ3: site_control_document_date | AK3: resolutions_complete_flag | AL3: local_approval_complete_flag | AM3: third_party_reports_complete_flag | AN3: esa_complete_flag | AO3: market_analysis_complete_flag | AP3: appraisal_complete_flag | AQ3: scr_complete_flag | AR3: feasibility_report_complete_flag | AS3: deficiency_notice_issued_flag | AT3: deficiency_notice_date | AU3: deficiency_response_due_date | AV3: deficiency_cleared_flag | AW3: deficiency_cleared_date | AX3: material_deficiency_flag | AY3: underwriting_complete_flag | AZ3: underwriting_pass_flag | BA3: financial_feasible_flag | BB3: deconcentration_compliant_flag | BC3: one_mile_rule_compliant_flag | BD3: two_mile_same_year_rule_relevant_flag | BE3: existing_lura_conflict_flag | BF3: rural_area_flag | BG3: urban_area_flag | BH3: qct_flag | BI3: high_opportunity_override_flag | BJ3: streamlined_eligible_flag | BK3: board_review_required_flag | BL3: chapter12_issue_flag | BM3: ready_for_determination_notice_flag | BN3: ready_for_board_flag | BO3: pipeline_entry_date | BP3: carryforward_from_prior_log_flag | BQ3: new_project_this_snapshot_flag | BR3: all_manual_boxes_checked_flag | BS3: project_ready_now_flag | BT3: pipeline_seniority_rank_manual | BU3: predicted_next_status | BV3: predicted_next_path | BW3: predicted_blocker_code | BX3: predicted_reason_1 | BY3: predicted_reason_2 | BZ3: predicted_reason_3 | CA3: predicted_relative_rank | CB3: predicted_advance_flag | CC3: notes | CD3: applicant_contact | CE3: applicant_phone | CF3: applicant_email | CG3: bond_issuer_contact | CH3: bond_issuer_phone
A4: 2026-02-10 | B4: 2026-02-10 | C4: 25427 | D4: 24426 | E4: Bay Terrace | F4: Baytown | G4: Harris | H4: 6 | I4: 1502 Nolan Road | J4: 77520 | K4: 45659 | L4: Closed | M4: 45757 | N4: 45834 | O4: 45670 | P4: 45850 | R4: Acq/Rehab | S4: General | T4: 130 | U4: 130 | X4: Southeast Texas HFC | Y4: Local HFC | Z4: 22500000 | AB4: 1300304 | AC4: 1285865 | AD4: 1250000 | AE4: 1250000 | AF4: N | AG4: N | AI4: Y | AK4: Y | AL4: Y | AM4: Y | AS4: N | AX4: N | AY4: Y | AZ4: Y | BA4: Y | BB4: Y | BC4: Y | BE4: N | BJ4: Y | BK4: N | BL4: N | BM4: Y | BN4: Y | BO4: 45659 | BP4: Y | BQ4: N | BR4: =IF(COUNTIF(AI4:BM4,"N")+COUNTBLANK(AI4:BM4)=0,"Y","N") | BS4: =IF(AND(BR4="Y",OR(L4="Submitted",L4="Under Review")),"Y",IF(L4="Closed","Y","N")) | BT4: 5 | BU4: =Rule_Flags!Q3 | BV4: =Rule_Flags!P3 | BW4: =IF(Rule_Flags!E3=1,"SITE_CONTROL",IF(Rule_Flags!F3=1,"APPROVALS",IF(Rule_Flags!G3=1,"REPORTS",IF(Rule_Flags!H3=1,"DEFICIENCY",IF(Rule_Flags!I3=1,"UNDERWRITING",IF(Rule_Flags!J3=1,"COMPLIANCE","")))))) | BX4: =IF(BW4="SITE_CONTROL","Site control missing or invalid",IF(BW4="APPROVALS","Required approvals or resolutions incomplete",IF(BW4="REPORTS","Required third-party reports incomplete",IF(BW4="DEFICIENCY","Unresolved deficiency or material deficiency",IF(BW4="UNDERWRITING","Underwriting / feasibility not passed",IF(BW4="COMPLIANCE","Deconcentration, one-mile, LURA, or Chapter 12 issue","Ready under current engine rules")))))) | BY4: =IF(BV4="Determination Notice","Streamlined + DN-ready assumptions satisfied",IF(BV4="Board","Board-required or board-ready assumptions satisfied","")) | BZ4: =IF(AND(BP4="Y",BQ4<>"Y"),"Carryforward project retains queue priority",IF(BQ4="Y","New project enters behind carryforward projects","")) | CA4: =_xludf.RANK.EQ(Rule_Flags!O3,Rule_Flags!$O$3:$O$402,0) | CB4: =IF(OR(BU4="Determination Notice Issued",BU4="Board",BU4="Closed"),"Y","N") | CD4: Steve Anderson | CE4: (650) 400-8553 | CF4: steve@anderson.org | CG4: Ron Williams | CH4: (281) 484-4663
A5: 2026-02-10 | B5: 2026-02-10 | C5: 25428 | D5: 24434 | E5: Independence Village | F5: Amarillo | G5: Randall | H5: 1 | I5: 4700 Virginia | J5: 79109 | K5: 45659 | L5: Withdrawn | M5: 45820 | O5: 45723 | P5: 45903 | R5: Acq/Rehab | S5: Elderly | T5: 150 | U5: 150 | X5: Panhandle Regional HFC | Y5: Local HFC | Z5: 25000000 | AB5: 1324312 | AD5: 463534 | AF5: N | AG5: N | AI5: Y | AK5: Y | AL5: Y | AM5: Y | AS5: N | AX5: N | AY5: Y | AZ5: Y | BA5: Y | BB5: Y | BC5: Y | BE5: N | BJ5: Y | BK5: N | BL5: N | BM5: Y | BN5: Y | BO5: 45659 | BP5: Y | BQ5: N | BR5: =IF(COUNTIF(AI5:BM5,"N")+COUNTBLANK(AI5:BM5)=0,"Y","N") | BS5: =IF(AND(BR5="Y",OR(L5="Submitted",L5="Under Review")),"Y",IF(L5="Closed","Y","N")) | BT5: 6 | BU5: =Rule_Flags!Q4 | BV5: =Rule_Flags!P4 | BW5: =IF(Rule_Flags!E4=1,"SITE_CONTROL",IF(Rule_Flags!F4=1,"APPROVALS",IF(Rule_Flags!G4=1,"REPORTS",IF(Rule_Flags!H4=1,"DEFICIENCY",IF(Rule_Flags!I4=1,"UNDERWRITING",IF(Rule_Flags!J4=1,"COMPLIANCE","")))))) | BX5: =IF(BW5="SITE_CONTROL","Site control missing or invalid",IF(BW5="APPROVALS","Required approvals or resolutions incomplete",IF(BW5="REPORTS","Required third-party reports incomplete",IF(BW5="DEFICIENCY","Unresolved deficiency or material deficiency",IF(BW5="UNDERWRITING","Underwriting / feasibility not passed",IF(BW5="COMPLIANCE","Deconcentration, one-mile, LURA, or Chapter 12 issue","Ready under current engine rules")))))) | BY5: =IF(BV5="Determination Notice","Streamlined + DN-ready assumptions satisfied",IF(BV5="Board","Board-required or board-ready assumptions satisfied","")) | BZ5: =IF(AND(BP5="Y",BQ5<>"Y"),"Carryforward project retains queue priority",IF(BQ5="Y","New project enters behind carryforward projects","")) | CA5: =_xludf.RANK.EQ(Rule_Flags!O4,Rule_Flags!$O$3:$O$402,0) | CB5: =IF(OR(BU5="Determination Notice Issued",BU5="Board",BU5="Closed"),"Y","N") | CD5: Rae Wilder | CE5: (805) 413-0672 | CF5: rachel.posthumus@ccinvest.com | CG5: Michael Carr | CH5: (806) 360-2060
A6: 2026-02-10 | B6: 2026-02-10 | C6: 25420 | E6: The Bloom at Lamar Square | F6: Austin | G6: Travis | H6: 7 | I6: 1326 & 1328 Lamar Square Drive | J6: 78704 | K6: 45659 | L6: Withdrawn | M6: 45757 | N6: 45880 | O6: 45880 | P6: 46060 | R6: New Construction | S6: Supportive Housing | T6: 58 | U6: 58 | X6: TSAHC | Y6: Other | Z6: 16500000 | AB6: 903744 | AC6: 903744 | AD6: 900000 | AF6: N | AG6: Y | AI6: Y | AK6: Y | AL6: Y | AM6: Y | AS6: N | AX6: N | AY6: Y | AZ6: Y | BA6: Y | BB6: Y | BC6: Y | BE6: N | BJ6: Y | BK6: N | BL6: N | BM6: Y | BN6: Y | BO6: 45659 | BP6: Y | BQ6: N | BR6: =IF(COUNTIF(AI6:BM6,"N")+COUNTBLANK(AI6:BM6)=0,"Y","N") | BS6: =IF(AND(BR6="Y",OR(L6="Submitted",L6="Under Review")),"Y",IF(L6="Closed","Y","N")) | BT6: 4 | BU6: =Rule_Flags!Q5 | BV6: =Rule_Flags!P5 | BW6: =IF(Rule_Flags!E5=1,"SITE_CONTROL",IF(Rule_Flags!F5=1,"APPROVALS",IF(Rule_Flags!G5=1,"REPORTS",IF(Rule_Flags!H5=1,"DEFICIENCY",IF(Rule_Flags!I5=1,"UNDERWRITING",IF(Rule_Flags!J5=1,"COMPLIANCE","")))))) | BX6: =IF(BW6="SITE_CONTROL","Site control missing or invalid",IF(BW6="APPROVALS","Required approvals or resolutions incomplete",IF(BW6="REPORTS","Required third-party reports incomplete",IF(BW6="DEFICIENCY","Unresolved deficiency or material deficiency",IF(BW6="UNDERWRITING","Underwriting / feasibility not passed",IF(BW6="COMPLIANCE","Deconcentration, one-mile, LURA, or Chapter 12 issue","Ready under current engine rules")))))) | BY6: =IF(BV6="Determination Notice","Streamlined + DN-ready assumptions satisfied",IF(BV6="Board","Board-required or board-ready assumptions satisfied","")) | BZ6: =IF(AND(BP6="Y",BQ6<>"Y"),"Carryforward project retains queue priority",IF(BQ6="Y","New project enters behind carryforward projects","")) | CA6: =_xludf.RANK.EQ(Rule_Flags!O5,Rule_Flags!$O$3:$O$402,0) | CB6: =IF(OR(BU6="Determination Notice Issued",BU6="Board",BU6="Closed"),"Y","N") | CC6: construction_type mapped from raw 'NC' to 'New Construction'; property_tax_exemption normalized from 'Y (50%)' to 'Y' | CD6: Walter Moreau | CE6: (512) 610-4016 | CF6: walter.moreau@foundcom.org | CG6: David Danenfelzer | CH6: (512) 477-3562
A7: 2026-02-10 | B7: 2026-02-10 | C7: 25429 | E7: Huntington Place Senior Little Elm | F7: Little Elm | G7: Denton | H7: 3 | I7: NEQ Navo Road and Union Park Blvd | J7: 76227 | K7: 45663 | L7: Closed | M7: 45757 | N7: 45769 | O7: 45670 | P7: 45850 | R7: New Construction | S7: Elderly | T7: 198 | U7: 198 | X7: THF PFC | Y7: Other | Z7: 35000000 | AB7: 1987061 | AC7: 1987061 | AF7: N | AG7: Y | AH7: Y | AI7: Y | AK7: Y | AL7: Y | AM7: Y | AS7: N | AX7: N | AY7: Y | AZ7: Y | BA7: Y | BB7: Y | BC7: Y | BE7: N | BJ7: Y | BK7: N | BL7: N | BM7: Y | BN7: Y | BO7: 45663 | BP7: Y | BQ7: N | BR7: =IF(COUNTIF(AI7:BM7,"N")+COUNTBLANK(AI7:BM7)=0,"Y","N") | BS7: =IF(AND(BR7="Y",OR(L7="Submitted",L7="Under Review")),"Y",IF(L7="Closed","Y","N")) | BT7: 7 | BU7: =Rule_Flags!Q6 | BV7: =Rule_Flags!P6 | BW7: =IF(Rule_Flags!E6=1,"SITE_CONTROL",IF(Rule_Flags!F6=1,"APPROVALS",IF(Rule_Flags!G6=1,"REPORTS",IF(Rule_Flags!H6=1,"DEFICIENCY",IF(Rule_Flags!I6=1,"UNDERWRITING",IF(Rule_Flags!J6=1,"COMPLIANCE","")))))) | BX7: =IF(BW7="SITE_CONTROL","Site control missing or invalid",IF(BW7="APPROVALS","Required approvals or resolutions incomplete",IF(BW7="REPORTS","Required third-party reports incomplete",IF(BW7="DEFICIENCY","Unresolved deficiency or material deficiency",IF(BW7="UNDERWRITING","Underwriting / feasibility not passed",IF(BW7="COMPLIANCE","Deconcentration, one-mile, LURA, or Chapter 12 issue","Ready under current engine rules")))))) | BY7: =IF(BV7="Determination Notice","Streamlined + DN-ready assumptions satisfied",IF(BV7="Board","Board-required or board-ready assumptions satisfied","")) | BZ7: =IF(AND(BP7="Y",BQ7<>"Y"),"Carryforward project retains queue priority",IF(BQ7="Y","New project enters behind carryforward projects","")) | CA7: =_xludf.RANK.EQ(Rule_Flags!O6,Rule_Flags!$O$3:$O$402,0) | CB7: =IF(OR(BU7="Determination Notice Issued",BU7="Board",BU7="Closed"),"Y","N") | CC7: construction_type mapped from raw 'NC' to 'New Construction' | CD7: Ryan Combs | CE7: (512) 983-0422 | CF7: ryan@crossdevelopment.net | CG7: Jonathan Coreas | CH7: (830) 693-8100
A8: 2026-02-10 | B8: 2026-02-10 | C8: 25415 | D8: 8417 | E8: Seville Apartments | F8: Beaumont | G8: Jefferson | H8: 5 | I8: 4325 Crow Road | J8: 77706 | K8: 45665 | L8: Closed | M8: 45785 | N8: 45811 | O8: 45667 | P8: 45847 | R8: Acq/Rehab | S8: Elderly | T8: 90 | U8: 90 | X8: Jefferson County HFC | Y8: Local HFC | Z8: 10000000 | AB8: 645144 | AC8: 645144 | AF8: N | AG8: Y | AI8: Y | AK8: Y | AL8: Y | AM8: Y | AS8: N | AX8: N | AY8: Y | AZ8: Y | BA8: Y | BB8: Y | BC8: Y | BE8: N | BJ8: Y | BK8: N | BL8: N | BM8: Y | BN8: Y | BO8: 45665 | BP8: Y | BQ8: N | BR8: =IF(COUNTIF(AI8:BM8,"N")+COUNTBLANK(AI8:BM8)=0,"Y","N") | BS8: =IF(AND(BR8="Y",OR(L8="Submitted",L8="Under Review")),"Y",IF(L8="Closed","Y","N")) | BT8: 11 | BU8: =Rule_Flags!Q7 | BV8: =Rule_Flags!P7 | BW8: =IF(Rule_Flags!E7=1,"SITE_CONTROL",IF(Rule_Flags!F7=1,"APPROVALS",IF(Rule_Flags!G7=1,"REPORTS",IF(Rule_Flags!H7=1,"DEFICIENCY",IF(Rule_Flags!I7=1,"UNDERWRITING",IF(Rule_Flags!J7=1,"COMPLIANCE","")))))) | BX8: =IF(BW8="SITE_CONTROL","Site control missing or invalid",IF(BW8="APPROVALS","Required approvals or resolutions incomplete",IF(BW8="REPORTS","Required third-party reports incomplete",IF(BW8="DEFICIENCY","Unresolved deficiency or material deficiency",IF(BW8="UNDERWRITING","Underwriting / feasibility not passed",IF(BW8="COMPLIANCE","Deconcentration, one-mile, LURA, or Chapter 12 issue","Ready under current engine rules")))))) | BY8: =IF(BV8="Determination Notice","Streamlined + DN-ready assumptions satisfied",IF(BV8="Board","Board-required or board-ready assumptions satisfied","")) | BZ8: =IF(AND(BP8="Y",BQ8<>"Y"),"Carryforward project retains queue priority",IF(BQ8="Y","New project enters behind carryforward projects","")) | CA8: =_xludf.RANK.EQ(Rule_Flags!O7,Rule_Flags!$O$3:$O$402,0) | CB8: =IF(OR(BU8="Determination Notice Issued",BU8="Board",BU8="Closed"),"Y","N") | CD8: Andrew Bennett | CE8: (720) 749-3206 | CF8: abennett@steelellc.com | CG8: Jeff Branick | CH8: (409) 654-6730
A9: 2026-02-10 | B9: 2026-02-10 | C9: 25409 | D9: 060628 | E9: Lancaster Apartments | F9: Katy | G9: Harris | H9: 6 | I9: 20100 Park Row Boulevard | J9: 77449 | K9: 45665 | L9: Closed | M9: 45757 | N9: 45772 | O9: 45670 | P9: 45850 | R9: Acq/Rehab | S9: General | T9: 252 | U9: 252 | X9: HHA Fountainview PFC | Y9: Other | Z9: 30000000 | AB9: 1710060 | AC9: 1710060 | AD9: 350000 | AF9: N | AG9: Y | AH9: Y | AI9: Y | AK9: Y | AL9: Y | AM9: Y | AS9: N | AX9: N | AY9: Y | AZ9: Y | BA9: Y | BB9: Y | BC9: Y | BE9: N | BJ9: Y | BK9: N | BL9: N | BM9: Y | BN9: Y | BO9: 45665 | BP9: Y | BQ9: N | BR9: =IF(COUNTIF(AI9:BM9,"N")+COUNTBLANK(AI9:BM9)=0,"Y","N") | BS9: =IF(AND(BR9="Y",OR(L9="Submitted",L9="Under Review")),"Y",IF(L9="Closed","Y","N")) | BT9: 8 | BU9: =Rule_Flags!Q8 | BV9: =Rule_Flags!P8 | BW9: =IF(Rule_Flags!E8=1,"SITE_CONTROL",IF(Rule_Flags!F8=1,"APPROVALS",IF(Rule_Flags!G8=1,"REPORTS",IF(Rule_Flags!H8=1,"DEFICIENCY",IF(Rule_Flags!I8=1,"UNDERWRITING",IF(Rule_Flags!J8=1,"COMPLIANCE","")))))) | BX9: =IF(BW9="SITE_CONTROL","Site control missing or invalid",IF(BW9="APPROVALS","Required approvals or resolutions incomplete",IF(BW9="REPORTS","Required third-party reports incomplete",IF(BW9="DEFICIENCY","Unresolved deficiency or material deficiency",IF(BW9="UNDERWRITING","Underwriting / feasibility not passed",IF(BW9="COMPLIANCE","Deconcentration, one-mile, LURA, or Chapter 12 issue","Ready under current engine rules")))))) | BY9: =IF(BV9="Determination Notice","Streamlined + DN-ready assumptions satisfied",IF(BV9="Board","Board-required or board-ready assumptions satisfied","")) | BZ9: =IF(AND(BP9="Y",BQ9<>"Y"),"Carryforward project retains queue priority",IF(BQ9="Y","New project enters behind carryforward projects","")) | CA9: =_xludf.RANK.EQ(Rule_Flags!O8,Rule_Flags!$O$3:$O$402,0) | CB9: =IF(OR(BU9="Determination Notice Issued",BU9="Board",BU9="Closed"),"Y","N") | CD9: Jeremy Bartholomew | CE9: (713) 334-5514 | CF9: jeremy@resolutioncompanies.com | CG9: Jennine Hovell-Cox | CH9: (713) 260-0501
A10: 2026-02-10 | B10: 2026-02-10 | C10: 25410 | D10: 07433 | E10: Regency Park | F10: Houston | G10: Harris | H10: 6 | I10: 10600 Southown Trace Trail | J10: 77034 | K10: 45665 | L10: Closed | M10: 45757 | N10: 45772 | O10: 45670 | P10: 45850 | R10: Acq/Rehab | S10: General | T10: 252 | U10: 252 | X10: HHA Fountainview PFC | Y10: Other | Z10: 30000000 | AB10: 1408353 | AC10: 1408353 | AD10: 470000 | AF10: N | AG10: Y | AH10: Y | AI10: Y | AK10: Y | AL10: Y | AM10: Y | AS10: N | AX10: N | AY10: Y | AZ10: Y | BA10: Y | BB10: Y | BC10: Y | BE10: N | BJ10: Y | BK10: N | BL10: N | BM10: Y | BN10: Y | BO10: 45665 | BP10: Y | BQ10: N | BR10: =IF(COUNTIF(AI10:BM10,"N")+COUNTBLANK(AI10:BM10)=0,"Y","N") | BS10: =IF(AND(BR10="Y",OR(L10="Submitted",L10="Under Review")),"Y",IF(L10="Closed","Y","N")) | BT10: 9 | BU10: =Rule_Flags!Q9 | BV10: =Rule_Flags!P9 | BW10: =IF(Rule_Flags!E9=1,"SITE_CONTROL",IF(Rule_Flags!F9=1,"APPROVALS",IF(Rule_Flags!G9=1,"REPORTS",IF(Rule_Flags!H9=1,"DEFICIENCY",IF(Rule_Flags!I9=1,"UNDERWRITING",IF(Rule_Flags!J9=1,"COMPLIANCE","")))))) | BX10: =IF(BW10="SITE_CONTROL","Site control missing or invalid",IF(BW10="APPROVALS","Required approvals or resolutions incomplete",IF(BW10="REPORTS","Required third-party reports incomplete",IF(BW10="DEFICIENCY","Unresolved deficiency or material deficiency",IF(BW10="UNDERWRITING","Underwriting / feasibility not passed",IF(BW10="COMPLIANCE","Deconcentration, one-mile, LURA, or Chapter 12 issue","Ready under current engine rules")))))) | BY10: =IF(BV10="Determination Notice","Streamlined + DN-ready assumptions satisfied",IF(BV10="Board","Board-required or board-ready assumptions satisfied","")) | BZ10: =IF(AND(BP10="Y",BQ10<>"Y"),"Carryforward project retains queue priority",IF(BQ10="Y","New project enters behind carryforward projects","")) | CA10: =_xludf.RANK.EQ(Rule_Flags!O9,Rule_Flags!$O$3:$O$402,0) | CB10: =IF(OR(BU10="Determination Notice Issued",BU10="Board",BU10="Closed"),"Y","N") | CD10: Jeremy Bartholomew | CE10: (713) 334-5514 | CF10: jeremy@resolutioncompanies.com | CG10: Jennine Hovell-Cox | CH10: (713) 260-0501
A11: 2026-02-10 | B11: 2026-02-10 | C11: 25411 | D11: 01456 | E11: Sugar Creek | F11: Houston | G11: Harris | H11: 6 | I11: 11501 West Road | J11: 77065 | K11: 45665 | L11: Closed | M11: 45757 | N11: 45772 | O11: 45672 | P11: 45852 | R11: Acq/Rehab | S11: General | T11: 240 | U11: 240 | X11: HHA Fountainview PFC | Y11: Other | Z11: 28000000 | AB11: 1442123 | AC11: 1442123 | AF11: N | AG11: Y | AH11: Y | AI11: Y | AK11: Y | AL11: Y | AM11: Y | AS11: N | AX11: N | AY11: Y | AZ11: Y | BA11: Y | BB11: Y | BC11: Y | BE11: N | BJ11: Y | BK11: N | BL11: N | BM11: Y | BN11: Y | BO11: 45665 | BP11: Y | BQ11: N | BR11: =IF(COUNTIF(AI11:BM11,"N")+COUNTBLANK(AI11:BM11)=0,"Y","N") | BS11: =IF(AND(BR11="Y",OR(L11="Submitted",L11="Under Review")),"Y",IF(L11="Closed","Y","N")) | BT11: 10 | BU11: =Rule_Flags!Q10 | BV11: =Rule_Flags!P10 | BW11: =IF(Rule_Flags!E10=1,"SITE_CONTROL",IF(Rule_Flags!F10=1,"APPROVALS",IF(Rule_Flags!G10=1,"REPORTS",IF(Rule_Flags!H10=1,"DEFICIENCY",IF(Rule_Flags!I10=1,"UNDERWRITING",IF(Rule_Flags!J10=1,"COMPLIANCE","")))))) | BX11: =IF(BW11="SITE_CONTROL","Site control missing or invalid",IF(BW11="APPROVALS","Required approvals or resolutions incomplete",IF(BW11="REPORTS","Required third-party reports incomplete",IF(BW11="DEFICIENCY","Unresolved deficiency or material deficiency",IF(BW11="UNDERWRITING","Underwriting / feasibility not passed",IF(BW11="COMPLIANCE","Deconcentration, one-mile, LURA, or Chapter 12 issue","Ready under current engine rules")))))) | BY11: =IF(BV11="Determination Notice","Streamlined + DN-ready assumptions satisfied",IF(BV11="Board","Board-required or board-ready assumptions satisfied","")) | BZ11: =IF(AND(BP11="Y",BQ11<>"Y"),"Carryforward project retains queue priority",IF(BQ11="Y","New project enters behind carryforward projects","")) | CA11: =_xludf.RANK.EQ(Rule_Flags!O10,Rule_Flags!$O$3:$O$402,0) | CB11: =IF(OR(BU11="Determination Notice Issued",BU11="Board",BU11="Closed"),"Y","N") | CD11: Jeremy Bartholomew | CE11: (713) 334-5514 | CF11: jeremy@resolutioncompanies.com | CG11: Jennine Hovell-Cox | CH11: (713) 260-0501
A12: 2026-02-10 | B12: 2026-02-10 | C12: 25433 | E12: Brady Village | F12: Lancaster | G12: Dallas | H12: 3 | I12: Brady Drive and McKinney Drive | J12: 75146 | K12: 45666 | L12: Withdrawn | M12: 45820 | O12: 45667 | P12: 45847 | R12: Acq/Rehab | S12: General | T12: 60 | U12: 60 | X12: Texas Home Collaborative | Y12: Other | Z12: 25000000 | AB12: 752709 | AF12: N | AG12: N | AI12: Y | AK12: Y | AL12: Y | AM12: Y | AS12: N | AX12: N | AY12: Y | AZ12: Y | BA12: Y | BB12: Y | BC12: Y | BE12: N | BJ12: Y | BK12: N | BL12: N | BM12: Y | BN12: Y | BO12: 45666 | BP12: Y | BQ12: N | BR12: =IF(COUNTIF(AI12:BM12,"N")+COUNTBLANK(AI12:BM12)=0,"Y","N") | BS12: =IF(AND(BR12="Y",OR(L12="Submitted",L12="Under Review")),"Y",IF(L12="Closed","Y","N")) | BT12: 12 | BU12: =Rule_Flags!Q11 | BV12: =Rule_Flags!P11 | BW12: =IF(Rule_Flags!E11=1,"SITE_CONTROL",IF(Rule_Flags!F11=1,"APPROVALS",IF(Rule_Flags!G11=1,"REPORTS",IF(Rule_Flags!H11=1,"DEFICIENCY",IF(Rule_Flags!I11=1,"UNDERWRITING",IF(Rule_Flags!J11=1,"COMPLIANCE","")))))) | BX12: =IF(BW12="SITE_CONTROL","Site control missing or invalid",IF(BW12="APPROVALS","Required approvals or resolutions incomplete",IF(BW12="REPORTS","Required third-party reports incomplete",IF(BW12="DEFICIENCY","Unresolved deficiency or material deficiency",IF(BW12="UNDERWRITING","Underwriting / feasibility not passed",IF(BW12="COMPLIANCE","Deconcentration, one-mile, LURA, or Chapter 12 issue","Ready under current engine rules")))))) | BY12: =IF(BV12="Determination Notice","Streamlined + DN-ready assumptions satisfied",IF(BV12="Board","Board-required or board-ready assumptions satisfied","")) | BZ12: =IF(AND(BP12="Y",BQ12<>"Y"),"Carryforward project retains queue priority",IF(BQ12="Y","New project enters behind carryforward projects","")) | CA12: =_xludf.RANK.EQ(Rule_Flags!O11,Rule_Flags!$O$3:$O$402,0) | CB12: =IF(OR(BU12="Determination Notice Issued",BU12="Board",BU12="Closed"),"Y","N") | CD12: Melissa Fisher | CE12: (972) 701-5555 | CF12: mfisher@rise-residential.com | CG12: Antonio Williams | CH12: (903) 276-7557
A13: 2026-02-10 | B13: 2026-02-10 | C13: 25434 | D13: 9989 | E13: Seaport Village | F13: Galveston | G13: Galveston | H13: 6 | I13: 7200 Heards Lane | J13: 77551 | K13: 45666 | L13: Withdrawn | M13: 45820 | O13: 45667 | P13: 45847 | R13: Acq/Rehab | S13: General | T13: 192 | U13: 192 | X13: Texas Home Collaborative | Y13: Other | Z13: 25000000 | AB13: 1267031 | AF13: N | AG13: N | AI13: Y | AK13: Y | AL13: Y | AM13: Y | AS13: N | AX13: N | AY13: Y | AZ13: Y | BA13: Y | BB13: Y | BC13: Y | BE13: N | BJ13: Y | BK13: N | BL13: N | BM13: Y | BN13: Y | BO13: 45666 | BP13: Y | BQ13: N | BR13: =IF(COUNTIF(AI13:BM13,"N")+COUNTBLANK(AI13:BM13)=0,"Y","N") | BS13: =IF(AND(BR13="Y",OR(L13="Submitted",L13="Under Review")),"Y",IF(L13="Closed","Y","N")) | BT13: 13 | BU13: =Rule_Flags!Q12 | BV13: =Rule_Flags!P12 | BW13: =IF(Rule_Flags!E12=1,"SITE_CONTROL",IF(Rule_Flags!F12=1,"APPROVALS",IF(Rule_Flags!G12=1,"REPORTS",IF(Rule_Flags!H12=1,"DEFICIENCY",IF(Rule_Flags!I12=1,"UNDERWRITING",IF(Rule_Flags!J12=1,"COMPLIANCE","")))))) | BX13: =IF(BW13="SITE_CONTROL","Site control missing or invalid",IF(BW13="APPROVALS","Required approvals or resolutions incomplete",IF(BW13="REPORTS","Required third-party reports incomplete",IF(BW13="DEFICIENCY","Unresolved deficiency or material deficiency",IF(BW13="UNDERWRITING","Underwriting / feasibility not passed",IF(BW13="COMPLIANCE","Deconcentration, one-mile, LURA, or Chapter 12 issue","Ready under current engine rules")))))) | BY13: =IF(BV13="Determination Notice","Streamlined + DN-ready assumptions satisfied",IF(BV13="Board","Board-required or board-ready assumptions satisfied","")) | BZ13: =IF(AND(BP13="Y",BQ13<>"Y"),"Carryforward project retains queue priority",IF(BQ13="Y","New project enters behind carryforward projects","")) | CA13: =_xludf.RANK.EQ(Rule_Flags!O12,Rule_Flags!$O$3:$O$402,0) | CB13: =IF(OR(BU13="Determination Notice Issued",BU13="Board",BU13="Closed"),"Y","N") | CD13: Bill Fisher | CE13: (214) 608-7201 | CF13: bill.fisher@sonomaadvisors.com | CG13: Antonio Williams | CH13: (903) 276-7557
A14: 2026-02-10 | B14: 2026-02-10 | C14: 25435 | E14: Sienna Villas | F14: Freeport | G14: Brazoria | H14: 6 | I14: 902 North Avenue J | J14: 77541 | K14: 45666 | L14: Withdrawn | M14: 45820 | O14: 45883 | P14: 46063 | R14: Acq/Rehab | S14: General | T14: 156 | U14: 156 | X14: Texas Home Collaborative | Y14: Other | Z14: 20000000 | AB14: 1183699 | AF14: N | AG14: N | AI14: Y | AK14: Y | AL14: Y | AM14: Y | AS14: N | AX14: N | AY14: Y | AZ14: Y | BA14: Y | BB14: Y | BC14: Y | BE14: N | BJ14: Y | BK14: N | BL14: N | BM14: Y | BN14: Y | BO14: 45666 | BP14: Y | BQ14: N | BR14: =IF(COUNTIF(AI14:BM14,"N")+COUNTBLANK(AI14:BM14)=0,"Y","N") | BS14: =IF(AND(BR14="Y",OR(L14="Submitted",L14="Under Review")),"Y",IF(L14="Closed","Y","N")) | BT14: 14 | BU14: =Rule_Flags!Q13 | BV14: =Rule_Flags!P13 | BW14: =IF(Rule_Flags!E13=1,"SITE_CONTROL",IF(Rule_Flags!F13=1,"APPROVALS",IF(Rule_Flags!G13=1,"REPORTS",IF(Rule_Flags!H13=1,"DEFICIENCY",IF(Rule_Flags!I13=1,"UNDERWRITING",IF(Rule_Flags!J13=1,"COMPLIANCE","")))))) | BX14: =IF(BW14="SITE_CONTROL","Site control missing or invalid",IF(BW14="APPROVALS","Required approvals or resolutions incomplete",IF(BW14="REPORTS","Required third-party reports incomplete",IF(BW14="DEFICIENCY","Unresolved deficiency or material deficiency",IF(BW14="UNDERWRITING","Underwriting / feasibility not passed",IF(BW14="COMPLIANCE","Deconcentration, one-mile, LURA, or Chapter 12 issue","Ready under current engine rules")))))) | BY14: =IF(BV14="Determination Notice","Streamlined + DN-ready assumptions satisfied",IF(BV14="Board","Board-required or board-ready assumptions satisfied","")) | BZ14: =IF(AND(BP14="Y",BQ14<>"Y"),"Carryforward project retains queue priority",IF(BQ14="Y","New project enters behind carryforward projects","")) | CA14: =_xludf.RANK.EQ(Rule_Flags!O13,Rule_Flags!$O$3:$O$402,0) | CB14: =IF(OR(BU14="Determination Notice Issued",BU14="Board",BU14="Closed"),"Y","N") | CD14: Bill Fisher | CE14: (214) 608-7201 | CF14: bill.fisher@sonomaadvisors.com | CG14: Antonio Williams | CH14: (903) 276-7557
A15: 2026-02-10 | B15: 2026-02-10 | C15: 25441 | D15: 24445 | E15: Aureus at Whisper Hills | F15: San Marcos | G15: Hays | H15: 7 | I15: 538 Celebration Way | J15: 78666 | K15: 45667 | L15: Withdrawn | M15: 45785 | O15: 45671 | P15: 45851 | R15: New Construction | S15: Elderly | T15: 267 | U15: 267 | X15: SMHA Finance PFC | Y15: Other | Z15: 40000000 | AB15: 2915592 | AF15: N | AG15: Y | AH15: Y | AI15: Y | AK15: Y | AL15: Y | AM15: Y | AS15: N | AX15: N | AY15: Y | AZ15: Y | BA15: Y | BB15: Y | BC15: Y | BE15: N | BJ15: Y | BK15: N | BL15: N | BM15: Y | BN15: Y | BO15: 45667 | BP15: Y | BQ15: N | BR15: =IF(COUNTIF(AI15:BM15,"N")+COUNTBLANK(AI15:BM15)=0,"Y","N") | BS15: =IF(AND(BR15="Y",OR(L15="Submitted",L15="Under Review")),"Y",IF(L15="Closed","Y","N")) | BT15: 19 | BU15: =Rule_Flags!Q14 | BV15: =Rule_Flags!P14 | BW15: =IF(Rule_Flags!E14=1,"SITE_CONTROL",IF(Rule_Flags!F14=1,"APPROVALS",IF(Rule_Flags!G14=1,"REPORTS",IF(Rule_Flags!H14=1,"DEFICIENCY",IF(Rule_Flags!I14=1,"UNDERWRITING",IF(Rule_Flags!J14=1,"COMPLIANCE","")))))) | BX15: =IF(BW15="SITE_CONTROL","Site control missing or invalid",IF(BW15="APPROVALS","Required approvals or resolutions incomplete",IF(BW15="REPORTS","Required third-party reports incomplete",IF(BW15="DEFICIENCY","Unresolved deficiency or material deficiency",IF(BW15="UNDERWRITING","Underwriting / feasibility not passed",IF(BW15="COMPLIANCE","Deconcentration, one-mile, LURA, or Chapter 12 issue","Ready under current engine rules")))))) | BY15: =IF(BV15="Determination Notice","Streamlined + DN-ready assumptions satisfied",IF(BV15="Board","Board-required or board-ready assumptions satisfied","")) | BZ15: =IF(AND(BP15="Y",BQ15<>"Y"),"Carryforward project retains queue priority",IF(BQ15="Y","New project enters behind carryforward projects","")) | CA15: =_xludf.RANK.EQ(Rule_Flags!O14,Rule_Flags!$O$3:$O$402,0) | CB15: =IF(OR(BU15="Determination Notice Issued",BU15="Board",BU15="Closed"),"Y","N") | CC15: construction_type mapped from raw 'NC' to 'New Construction' | CD15: John Latham | CE15: (210) 354-3705 | CF15: john@missiondg.com | CG15: Lana Wagner | CH15: (512) 353-5058
A16: 2026-02-10 | B16: 2026-02-10 | C16: 25406 | D16: 04475 | E16: Fairlake Cove | F16: Houston | G16: Harris | H16: 6 | I16: 11100 E FM 1960 | J16: 77336 | K16: 45667 | L16: Withdrawn | M16: 45785 | O16: 45671 | P16: 45851 | R16: Acq/Rehab | S16: General | T16: 200 | U16: 200 | X16: HHA Fountainview PFC | Y16: Other | Z16: 40000000 | AB16: 1686761 | AF16: N | AG16: Y | AH16: Y | AI16: Y | AK16: Y | AL16: Y | AM16: Y | AS16: N | AX16: N | AY16: Y | AZ16: Y | BA16: Y | BB16: Y | BC16: Y | BE16: N | BJ16: Y | BK16: N | BL16: N | BM16: Y | BN16: Y | BO16: 45667 | BP16: Y | BQ16: N | BR16: =IF(COUNTIF(AI16:BM16,"N")+COUNTBLANK(AI16:BM16)=0,"Y","N") | BS16: =IF(AND(BR16="Y",OR(L16="Submitted",L16="Under Review")),"Y",IF(L16="Closed","Y","N")) | BT16: 16 | BU16: =Rule_Flags!Q15 | BV16: =Rule_Flags!P15 | BW16: =IF(Rule_Flags!E15=1,"SITE_CONTROL",IF(Rule_Flags!F15=1,"APPROVALS",IF(Rule_Flags!G15=1,"REPORTS",IF(Rule_Flags!H15=1,"DEFICIENCY",IF(Rule_Flags!I15=1,"UNDERWRITING",IF(Rule_Flags!J15=1,"COMPLIANCE","")))))) | BX16: =IF(BW16="SITE_CONTROL","Site control missing or invalid",IF(BW16="APPROVALS","Required approvals or resolutions incomplete",IF(BW16="REPORTS","Required third-party reports incomplete",IF(BW16="DEFICIENCY","Unresolved deficiency or material deficiency",IF(BW16="UNDERWRITING","Underwriting / feasibility not passed",IF(BW16="COMPLIANCE","Deconcentration, one-mile, LURA, or Chapter 12 issue","Ready under current engine rules")))))) | BY16: =IF(BV16="Determination Notice","Streamlined + DN-ready assumptions satisfied",IF(BV16="Board","Board-required or board-ready assumptions satisfied","")) | BZ16: =IF(AND(BP16="Y",BQ16<>"Y"),"Carryforward project retains queue priority",IF(BQ16="Y","New project enters behind carryforward projects","")) | CA16: =_xludf.RANK.EQ(Rule_Flags!O15,Rule_Flags!$O$3:$O$402,0) | CB16: =IF(OR(BU16="Determination Notice Issued",BU16="Board",BU16="Closed"),"Y","N") | CD16: Brad Fisher | CE16: (913) 787-1676 | CF16: bfisher@aprilhousing.com | CG16: Jennine Hovell-Cox | CH16: (713) 260-0501
A17: 2026-02-10 | B17: 2026-02-10 | C17: 25436 | E17: Jackson Apartments | F17: McAllen | G17: Hidalgo | H17: 11 | I17: 2200 W Jackson Avenue | J17: 78503 | K17: 45667 | L17: Withdrawn | M17: 45820 | O17: 45883 | P17: 46063 | R17: New Construction | S17: General | T17: 88 | U17: 88 | X17: Texas Home Collaborative | Y17: Other | Z17: 12000000 | AB17: 776722 | AF17: N | AG17: N | AI17: Y | AK17: Y | AL17: Y | AM17: Y | AS17: N | AX17: N | AY17: Y | AZ17: Y | BA17: Y | BB17: Y | BC17: Y | BE17: N | BJ17: Y | BK17: N | BL17: N | BM17: Y | BN17: Y | BO17: 45667 | BP17: Y | BQ17: N | BR17: =IF(COUNTIF(AI17:BM17,"N")+COUNTBLANK(AI17:BM17)=0,"Y","N") | BS17: =IF(AND(BR17="Y",OR(L17="Submitted",L17="Under Review")),"Y",IF(L17="Closed","Y","N")) | BT17: 18 | BU17: =Rule_Flags!Q16 | BV17: =Rule_Flags!P16 | BW17: =IF(Rule_Flags!E16=1,"SITE_CONTROL",IF(Rule_Flags!F16=1,"APPROVALS",IF(Rule_Flags!G16=1,"REPORTS",IF(Rule_Flags!H16=1,"DEFICIENCY",IF(Rule_Flags!I16=1,"UNDERWRITING",IF(Rule_Flags!J16=1,"COMPLIANCE","")))))) | BX17: =IF(BW17="SITE_CONTROL","Site control missing or invalid",IF(BW17="APPROVALS","Required approvals or resolutions incomplete",IF(BW17="REPORTS","Required third-party reports incomplete",IF(BW17="DEFICIENCY","Unresolved deficiency or material deficiency",IF(BW17="UNDERWRITING","Underwriting / feasibility not passed",IF(BW17="COMPLIANCE","Deconcentration, one-mile, LURA, or Chapter 12 issue","Ready under current engine rules")))))) | BY17: =IF(BV17="Determination Notice","Streamlined + DN-ready assumptions satisfied",IF(BV17="Board","Board-required or board-ready assumptions satisfied","")) | BZ17: =IF(AND(BP17="Y",BQ17<>"Y"),"Carryforward project retains queue priority",IF(BQ17="Y","New project enters behind carryforward projects","")) | CA17: =_xludf.RANK.EQ(Rule_Flags!O16,Rule_Flags!$O$3:$O$402,0) | CB17: =IF(OR(BU17="Determination Notice Issued",BU17="Board",BU17="Closed"),"Y","N") | CC17: construction_type mapped from raw 'NC' to 'New Construction' | CD17: Melissa Fisher | CE17: (972) 701-5555 | CF17: mfisher@rise-residential.com | CG17: Antonio Williams | CH17: (903) 276-7557
A18: 2026-02-10 | B18: 2026-02-10 | C18: 25405 | E18: HiLine Illinois | F18: Dallas | G18: Dallas | H18: 3 | I18: 4710 W Illinois Avenue | J18: 75211 | K18: 45667 | L18: Closed | M18: 45785 | N18: 45825 | O18: 45672 | P18: 45852 | R18: New Construction | S18: General | T18: 200 | U18: 200 | X18: Dallas HFC | Y18: Local HFC | Z18: 35000000 | AB18: 2784011 | AC18: 2784011 | AF18: N | AG18: Y | AI18: Y | AK18: Y | AL18: Y | AM18: Y | AS18: N | AX18: N | AY18: Y | AZ18: Y | BA18: Y | BB18: Y | BC18: Y | BE18: N | BJ18: Y | BK18: N | BL18: N | BM18: Y | BN18: Y | BO18: 45667 | BP18: Y | BQ18: N | BR18: =IF(COUNTIF(AI18:BM18,"N")+COUNTBLANK(AI18:BM18)=0,"Y","N") | BS18: =IF(AND(BR18="Y",OR(L18="Submitted",L18="Under Review")),"Y",IF(L18="Closed","Y","N")) | BT18: 15 | BU18: =Rule_Flags!Q17 | BV18: =Rule_Flags!P17 | BW18: =IF(Rule_Flags!E17=1,"SITE_CONTROL",IF(Rule_Flags!F17=1,"APPROVALS",IF(Rule_Flags!G17=1,"REPORTS",IF(Rule_Flags!H17=1,"DEFICIENCY",IF(Rule_Flags!I17=1,"UNDERWRITING",IF(Rule_Flags!J17=1,"COMPLIANCE","")))))) | BX18: =IF(BW18="SITE_CONTROL","Site control missing or invalid",IF(BW18="APPROVALS","Required approvals or resolutions incomplete",IF(BW18="REPORTS","Required third-party reports incomplete",IF(BW18="DEFICIENCY","Unresolved deficiency or material deficiency",IF(BW18="UNDERWRITING","Underwriting / feasibility not passed",IF(BW18="COMPLIANCE","Deconcentration, one-mile, LURA, or Chapter 12 issue","Ready under current engine rules")))))) | BY18: =IF(BV18="Determination Notice","Streamlined + DN-ready assumptions satisfied",IF(BV18="Board","Board-required or board-ready assumptions satisfied","")) | BZ18: =IF(AND(BP18="Y",BQ18<>"Y"),"Carryforward project retains queue priority",IF(BQ18="Y","New project enters behind carryforward projects","")) | CA18: =_xludf.RANK.EQ(Rule_Flags!O17,Rule_Flags!$O$3:$O$402,0) | CB18: =IF(OR(BU18="Determination Notice Issued",BU18="Board",BU18="Closed"),"Y","N") | CC18: construction_type mapped from raw 'NC' to 'New Construction' | CD18: Adrian Iglesias | CE18: (214)613-6569 | CF18: aiglesias@ghdevelopment.com | CG18: Aaron Eaquinto | CH18: (214) 670-4941
A19: 2026-02-10 | B19: 2026-02-10 | C19: 25413 | E19: Sunflower Terrace | F19: Houston | G19: Harris | H19: 6 | I19: 5050 Sunflower Street | J19: 77033 | K19: 45667 | L19: Closed | M19: 45757 | N19: 45779 | O19: 45671 | P19: 45851 | R19: Acq/Rehab | S19: General | T19: 160 | U19: 160 | X19: Houston HFC | Y19: Local HFC | Z19: 28000000 | AB19: 1996896 | AC19: 1996896 | AF19: N | AG19: Y | AI19: Y | AK19: Y | AL19: Y | AM19: Y | AS19: N | AX19: N | AY19: Y | AZ19: Y | BA19: Y | BB19: Y | BC19: Y | BE19: N | BJ19: Y | BK19: N | BL19: N | BM19: Y | BN19: Y | BO19: 45667 | BP19: Y | BQ19: N | BR19: =IF(COUNTIF(AI19:BM19,"N")+COUNTBLANK(AI19:BM19)=0,"Y","N") | BS19: =IF(AND(BR19="Y",OR(L19="Submitted",L19="Under Review")),"Y",IF(L19="Closed","Y","N")) | BT19: 17 | BU19: =Rule_Flags!Q18 | BV19: =Rule_Flags!P18 | BW19: =IF(Rule_Flags!E18=1,"SITE_CONTROL",IF(Rule_Flags!F18=1,"APPROVALS",IF(Rule_Flags!G18=1,"REPORTS",IF(Rule_Flags!H18=1,"DEFICIENCY",IF(Rule_Flags!I18=1,"UNDERWRITING",IF(Rule_Flags!J18=1,"COMPLIANCE","")))))) | BX19: =IF(BW19="SITE_CONTROL","Site control missing or invalid",IF(BW19="APPROVALS","Required approvals or resolutions incomplete",IF(BW19="REPORTS","Required third-party reports incomplete",IF(BW19="DEFICIENCY","Unresolved deficiency or material deficiency",IF(BW19="UNDERWRITING","Underwriting / feasibility not passed",IF(BW19="COMPLIANCE","Deconcentration, one-mile, LURA, or Chapter 12 issue","Ready under current engine rules")))))) | BY19: =IF(BV19="Determination Notice","Streamlined + DN-ready assumptions satisfied",IF(BV19="Board","Board-required or board-ready assumptions satisfied","")) | BZ19: =IF(AND(BP19="Y",BQ19<>"Y"),"Carryforward project retains queue priority",IF(BQ19="Y","New project enters behind carryforward projects","")) | CA19: =_xludf.RANK.EQ(Rule_Flags!O18,Rule_Flags!$O$3:$O$402,0) | CB19: =IF(OR(BU19="Determination Notice Issued",BU19="Board",BU19="Closed"),"Y","N") | CD19: Allan Izzo | CE19: (646) 825-7106 | CF19: allan.izzo@fairstead.com | CG19: Richard Mudd, Sr. | CH19: (713) 461-2749
A20: 2026-02-10 | B20: 2026-02-10 | C20: 25439 | D20: 95157 | E20: Pleasant Hill Village | F20: Houston | G20: Harris | H20: 6 | I20: 3814 Lyons Avenue | J20: 77020 | K20: 45670 | L20: Approved | M20: 45820 | N20: 45826 | O20: 45880 | P20: 46060 | R20: Acq/Rehab | S20: Elderly | T20: 165 | U20: 165 | X20: HHA Fountainview PFC | Y20: Other | Z20: 20000000 | AB20: 1176012 | AC20: 1176012 | AF20: N | AG20: Y | AH20: Y | AI20: Y | AK20: Y | AL20: Y | AM20: Y | AS20: N | AX20: N | AY20: Y | AZ20: Y | BA20: Y | BB20: Y | BC20: Y | BE20: N | BJ20: Y | BK20: N | BL20: N | BM20: Y | BN20: Y | BO20: 45670 | BP20: Y | BQ20: N | BR20: =IF(COUNTIF(AI20:BM20,"N")+COUNTBLANK(AI20:BM20)=0,"Y","N") | BS20: =IF(AND(BR20="Y",OR(L20="Submitted",L20="Under Review")),"Y",IF(L20="Closed","Y","N")) | BT20: 25 | BU20: =Rule_Flags!Q19 | BV20: =Rule_Flags!P19 | BW20: =IF(Rule_Flags!E19=1,"SITE_CONTROL",IF(Rule_Flags!F19=1,"APPROVALS",IF(Rule_Flags!G19=1,"REPORTS",IF(Rule_Flags!H19=1,"DEFICIENCY",IF(Rule_Flags!I19=1,"UNDERWRITING",IF(Rule_Flags!J19=1,"COMPLIANCE","")))))) | BX20: =IF(BW20="SITE_CONTROL","Site control missing or invalid",IF(BW20="APPROVALS","Required approvals or resolutions incomplete",IF(BW20="REPORTS","Required third-party reports incomplete",IF(BW20="DEFICIENCY","Unresolved deficiency or material deficiency",IF(BW20="UNDERWRITING","Underwriting / feasibility not passed",IF(BW20="COMPLIANCE","Deconcentration, one-mile, LURA, or Chapter 12 issue","Ready under current engine rules")))))) | BY20: =IF(BV20="Determination Notice","Streamlined + DN-ready assumptions satisfied",IF(BV20="Board","Board-required or board-ready assumptions satisfied","")) | BZ20: =IF(AND(BP20="Y",BQ20<>"Y"),"Carryforward project retains queue priority",IF(BQ20="Y","New project enters behind carryforward projects","")) | CA20: =_xludf.RANK.EQ(Rule_Flags!O19,Rule_Flags!$O$3:$O$402,0) | CB20: =IF(OR(BU20="Determination Notice Issued",BU20="Board",BU20="Closed"),"Y","N") | CD20: Harvey Clemons, Jr. | CE20: (713) 224-0052 | CF20: hclemons@aol.com | CG20: David Northern, Sr. | CH20: (713) 260-0522
A21: 2026-02-10 | B21: 2026-02-10 | C21: 25437 | E21: Manor Apartments | F21: Austin | G21: Travis | H21: 7 | I21: 6705 Manor Road | J21: 78723 | K21: 45670 | L21: Withdrawn | M21: 45785 | N21: 45800 | O21: 45671 | P21: 45851 | R21: New Construction | S21: General | T21: 181 | U21: 179 | X21: Travis County HFC | Y21: Local HFC | Z21: 35000000 | AB21: 2902773 | AC21: 2902773 | AF21: N | AG21: Y | AI21: Y | AK21: Y | AL21: Y | AM21: Y | AS21: N | AX21: N | AY21: Y | AZ21: Y | BA21: Y | BB21: Y | BC21: Y | BE21: N | BJ21: Y | BK21: N | BL21: N | BM21: Y | BN21: Y | BO21: 45670 | BP21: Y | BQ21: N | BR21: =IF(COUNTIF(AI21:BM21,"N")+COUNTBLANK(AI21:BM21)=0,"Y","N") | BS21: =IF(AND(BR21="Y",OR(L21="Submitted",L21="Under Review")),"Y",IF(L21="Closed","Y","N")) | BT21: 23 | BU21: =Rule_Flags!Q20 | BV21: =Rule_Flags!P20 | BW21: =IF(Rule_Flags!E20=1,"SITE_CONTROL",IF(Rule_Flags!F20=1,"APPROVALS",IF(Rule_Flags!G20=1,"REPORTS",IF(Rule_Flags!H20=1,"DEFICIENCY",IF(Rule_Flags!I20=1,"UNDERWRITING",IF(Rule_Flags!J20=1,"COMPLIANCE","")))))) | BX21: =IF(BW21="SITE_CONTROL","Site control missing or invalid",IF(BW21="APPROVALS","Required approvals or resolutions incomplete",IF(BW21="REPORTS","Required third-party reports incomplete",IF(BW21="DEFICIENCY","Unresolved deficiency or material deficiency",IF(BW21="UNDERWRITING","Underwriting / feasibility not passed",IF(BW21="COMPLIANCE","Deconcentration, one-mile, LURA, or Chapter 12 issue","Ready under current engine rules")))))) | BY21: =IF(BV21="Determination Notice","Streamlined + DN-ready assumptions satisfied",IF(BV21="Board","Board-required or board-ready assumptions satisfied","")) | BZ21: =IF(AND(BP21="Y",BQ21<>"Y"),"Carryforward project retains queue priority",IF(BQ21="Y","New project enters behind carryforward projects","")) | CA21: =_xludf.RANK.EQ(Rule_Flags!O20,Rule_Flags!$O$3:$O$402,0) | CB21: =IF(OR(BU21="Determination Notice Issued",BU21="Board",BU21="Closed"),"Y","N") | CC21: construction_type mapped from raw 'NC' to 'New Construction' | CD21: Chad Baker | CE21: (214) 295-5645 | CF21: cbaker@amtexhousing.com | CG21: Ana Everett | CH21: (512) 854-1745
A22: 2026-02-10 | B22: 2026-02-10 | C22: 25438 | D22: 538613 | E22: Britton's Place | F22: Houston | G22: Harris | H22: 6 | I22: 3730 Lyons Avenue | J22: 77020 | K22: 45670 | L22: Approved | M22: 45820 | N22: 45833 | O22: 45880 | P22: 46060 | R22: Acq/Rehab | S22: General | T22: 48 | U22: 48 | X22: HHA Fountainview PFC | Y22: Other | Z22: 20000000 | AB22: 466454 | AC22: 466454 | AF22: N | AG22: Y | AH22: Y | AI22: Y | AK22: Y | AL22: Y | AM22: Y | AS22: N | AX22: N | AY22: Y | AZ22: Y | BA22: Y | BB22: Y | BC22: Y | BE22: N | BJ22: Y | BK22: N | BL22: N | BM22: Y | BN22: Y | BO22: 45670 | BP22: Y | BQ22: N | BR22: =IF(COUNTIF(AI22:BM22,"N")+COUNTBLANK(AI22:BM22)=0,"Y","N") | BS22: =IF(AND(BR22="Y",OR(L22="Submitted",L22="Under Review")),"Y",IF(L22="Closed","Y","N")) | BT22: 24 | BU22: =Rule_Flags!Q21 | BV22: =Rule_Flags!P21 | BW22: =IF(Rule_Flags!E21=1,"SITE_CONTROL",IF(Rule_Flags!F21=1,"APPROVALS",IF(Rule_Flags!G21=1,"REPORTS",IF(Rule_Flags!H21=1,"DEFICIENCY",IF(Rule_Flags!I21=1,"UNDERWRITING",IF(Rule_Flags!J21=1,"COMPLIANCE","")))))) | BX22: =IF(BW22="SITE_CONTROL","Site control missing or invalid",IF(BW22="APPROVALS","Required approvals or resolutions incomplete",IF(BW22="REPORTS","Required third-party reports incomplete",IF(BW22="DEFICIENCY","Unresolved deficiency or material deficiency",IF(BW22="UNDERWRITING","Underwriting / feasibility not passed",IF(BW22="COMPLIANCE","Deconcentration, one-mile, LURA, or Chapter 12 issue","Ready under current engine rules")))))) | BY22: =IF(BV22="Determination Notice","Streamlined + DN-ready assumptions satisfied",IF(BV22="Board","Board-required or board-ready assumptions satisfied","")) | BZ22: =IF(AND(BP22="Y",BQ22<>"Y"),"Carryforward project retains queue priority",IF(BQ22="Y","New project enters behind carryforward projects","")) | CA22: =_xludf.RANK.EQ(Rule_Flags!O21,Rule_Flags!$O$3:$O$402,0) | CB22: =IF(OR(BU22="Determination Notice Issued",BU22="Board",BU22="Closed"),"Y","N") | CD22: Harvey Clemons, Jr. | CE22: (713) 224-0052 | CF22: hclemons@aol.com | CG22: David Northern, Sr. | CH22: (713) 260-0522
A23: 2026-02-10 | B23: 2026-02-10 | C23: 25417 | E23: Reserve at Ella | F23: Houston | G23: Harris | H23: 6 | I23: 867 Rushcreek Drive | J23: 77067 | K23: 45670 | L23: Withdrawn | M23: 45820 | O23: 45671 | P23: 45851 | R23: New Construction | S23: General | T23: 344 | U23: 344 | X23: HHA Fountainview PFC | Y23: Other | Z23: 50000000 | AB23: 3405323 | AF23: N | AG23: Y | AH23: Y | AI23: Y | AK23: Y | AL23: Y | AM23: Y | AS23: N | AX23: N | AY23: Y | AZ23: Y | BA23: Y | BB23: Y | BC23: Y | BE23: N | BJ23: Y | BK23: N | BL23: N | BM23: Y | BN23: Y | BO23: 45670 | BP23: Y | BQ23: N | BR23: =IF(COUNTIF(AI23:BM23,"N")+COUNTBLANK(AI23:BM23)=0,"Y","N") | BS23: =IF(AND(BR23="Y",OR(L23="Submitted",L23="Under Review")),"Y",IF(L23="Closed","Y","N")) | BT23: 22 | BU23: =Rule_Flags!Q22 | BV23: =Rule_Flags!P22 | BW23: =IF(Rule_Flags!E22=1,"SITE_CONTROL",IF(Rule_Flags!F22=1,"APPROVALS",IF(Rule_Flags!G22=1,"REPORTS",IF(Rule_Flags!H22=1,"DEFICIENCY",IF(Rule_Flags!I22=1,"UNDERWRITING",IF(Rule_Flags!J22=1,"COMPLIANCE","")))))) | BX23: =IF(BW23="SITE_CONTROL","Site control missing or invalid",IF(BW23="APPROVALS","Required approvals or resolutions incomplete",IF(BW23="REPORTS","Required third-party reports incomplete",IF(BW23="DEFICIENCY","Unresolved deficiency or material deficiency",IF(BW23="UNDERWRITING","Underwriting / feasibility not passed",IF(BW23="COMPLIANCE","Deconcentration, one-mile, LURA, or Chapter 12 issue","Ready under current engine rules")))))) | BY23: =IF(BV23="Determination Notice","Streamlined + DN-ready assumptions satisfied",IF(BV23="Board","Board-required or board-ready assumptions satisfied","")) | BZ23: =IF(AND(BP23="Y",BQ23<>"Y"),"Carryforward project retains queue priority",IF(BQ23="Y","New project enters behind carryforward projects","")) | CA23: =_xludf.RANK.EQ(Rule_Flags!O22,Rule_Flags!$O$3:$O$402,0) | CB23: =IF(OR(BU23="Determination Notice Issued",BU23="Board",BU23="Closed"),"Y","N") | CC23: construction_type mapped from raw 'NC' to 'New Construction' | CD23: Tony Ly | CE23: (713) 980-1622 | CF23: tonyly@stoacapitalpartners.com | CG23: Bill Walter | CH23: (512) 684-3842
A24: 2026-02-10 | B24: 2026-02-10 | C24: 25404 | E24: Torrington Briarwood | F24: Mesquite | G24: Dallas | H24: 3 | I24: 2250 Dean Street | J24: 75180 | K24: 45670 | L24: Closed | M24: 45785 | N24: 45433 | O24: 45671 | P24: 45851 | R24: New Construction | S24: General | T24: 313 | U24: 313 | X24: The Mesquite HFC | Y24: Local HFC | Z24: 50000000 | AB24: 4371047 | AC24: 4331927 | AF24: N | AG24: Y | AI24: Y | AK24: Y | AL24: Y | AM24: Y | AS24: N | AX24: N | AY24: Y | AZ24: Y | BA24: Y | BB24: Y | BC24: Y | BE24: N | BJ24: Y | BK24: N | BL24: N | BM24: Y | BN24: Y | BO24: 45670 | BP24: Y | BQ24: N | BR24: =IF(COUNTIF(AI24:BM24,"N")+COUNTBLANK(AI24:BM24)=0,"Y","N") | BS24: =IF(AND(BR24="Y",OR(L24="Submitted",L24="Under Review")),"Y",IF(L24="Closed","Y","N")) | BT24: 20 | BU24: =Rule_Flags!Q23 | BV24: =Rule_Flags!P23 | BW24: =IF(Rule_Flags!E23=1,"SITE_CONTROL",IF(Rule_Flags!F23=1,"APPROVALS",IF(Rule_Flags!G23=1,"REPORTS",IF(Rule_Flags!H23=1,"DEFICIENCY",IF(Rule_Flags!I23=1,"UNDERWRITING",IF(Rule_Flags!J23=1,"COMPLIANCE","")))))) | BX24: =IF(BW24="SITE_CONTROL","Site control missing or invalid",IF(BW24="APPROVALS","Required approvals or resolutions incomplete",IF(BW24="REPORTS","Required third-party reports incomplete",IF(BW24="DEFICIENCY","Unresolved deficiency or material deficiency",IF(BW24="UNDERWRITING","Underwriting / feasibility not passed",IF(BW24="COMPLIANCE","Deconcentration, one-mile, LURA, or Chapter 12 issue","Ready under current engine rules")))))) | BY24: =IF(BV24="Determination Notice","Streamlined + DN-ready assumptions satisfied",IF(BV24="Board","Board-required or board-ready assumptions satisfied","")) | BZ24: =IF(AND(BP24="Y",BQ24<>"Y"),"Carryforward project retains queue priority",IF(BQ24="Y","New project enters behind carryforward projects","")) | CA24: =_xludf.RANK.EQ(Rule_Flags!O23,Rule_Flags!$O$3:$O$402,0) | CB24: =IF(OR(BU24="Determination Notice Issued",BU24="Board",BU24="Closed"),"Y","N") | CC24: construction_type mapped from raw 'NC' to 'New Construction' | CD24: Karsten Lowe | CE24: (210) 493-8633 | CF24: Karsten.Lowe@jpi.com | CG24: Ted Chinn | CH24: (972) 216-6287
A25: 2026-02-10 | B25: 2026-02-10 | C25: 25412 | D25: 07457 | E25: Wyndham Park | F25: Baytown | G25: Harris | H25: 6 | I25: 2700 Rollingbrook Drive | J25: 77521 | K25: 45670 | L25: Closed | M25: 45785 | N25: 45811 | O25: 45673 | P25: 45853 | R25: Acq/Rehab | S25: Elderly | T25: 184 | U25: 184 | X25: Southeast Texas HFC | Y25: Local HFC | Z25: 20000000 | AB25: 986417 | AC25: 986417 | AF25: N | AG25: Y | AI25: Y | AK25: Y | AL25: Y | AM25: Y | AS25: N | AX25: N | AY25: Y | AZ25: Y | BA25: Y | BB25: Y | BC25: Y | BE25: N | BJ25: Y | BK25: N | BL25: N | BM25: Y | BN25: Y | BO25: 45670 | BP25: Y | BQ25: N | BR25: =IF(COUNTIF(AI25:BM25,"N")+COUNTBLANK(AI25:BM25)=0,"Y","N") | BS25: =IF(AND(BR25="Y",OR(L25="Submitted",L25="Under Review")),"Y",IF(L25="Closed","Y","N")) | BT25: 21 | BU25: =Rule_Flags!Q24 | BV25: =Rule_Flags!P24 | BW25: =IF(Rule_Flags!E24=1,"SITE_CONTROL",IF(Rule_Flags!F24=1,"APPROVALS",IF(Rule_Flags!G24=1,"REPORTS",IF(Rule_Flags!H24=1,"DEFICIENCY",IF(Rule_Flags!I24=1,"UNDERWRITING",IF(Rule_Flags!J24=1,"COMPLIANCE","")))))) | BX25: =IF(BW25="SITE_CONTROL","Site control missing or invalid",IF(BW25="APPROVALS","Required approvals or resolutions incomplete",IF(BW25="REPORTS","Required third-party reports incomplete",IF(BW25="DEFICIENCY","Unresolved deficiency or material deficiency",IF(BW25="UNDERWRITING","Underwriting / feasibility not passed",IF(BW25="COMPLIANCE","Deconcentration, one-mile, LURA, or Chapter 12 issue","Ready under current engine rules")))))) | BY25: =IF(BV25="Determination Notice","Streamlined + DN-ready assumptions satisfied",IF(BV25="Board","Board-required or board-ready assumptions satisfied","")) | BZ25: =IF(AND(BP25="Y",BQ25<>"Y"),"Carryforward project retains queue priority",IF(BQ25="Y","New project enters behind carryforward projects","")) | CA25: =_xludf.RANK.EQ(Rule_Flags!O24,Rule_Flags!$O$3:$O$402,0) | CB25: =IF(OR(BU25="Determination Notice Issued",BU25="Board",BU25="Closed"),"Y","N") | CD25: Jeremy Bartholomew | CE25: (713) 334-5514 | CF25: jeremy@resolutioncompanies.com | CG25: Ron Williams | CH25: (281) 484-4663
A26: 2026-02-10 | B26: 2026-02-10 | C26: 21608S | D26: 21608 | E26: Fiji Lofts | F26: Dallas | G26: Dallas | H26: 3 | I26: 301 S. Corinth Road | J26: 75203 | K26: 45525 | L26: Active | M26: 46037 | O26: 46057 | P26: 46229 | R26: New Construction | S26: General | T26: 204 | U26: 204 | X26: TDHCA | Y26: TDHCA | Z26: 6000000 | AB26: 2885077 | AF26: N | AG26: Y | AI26: Y | AK26: Y | AL26: Y | AM26: Y | AS26: N | AX26: N | AY26: Y | AZ26: Y | BA26: Y | BB26: Y | BC26: Y | BE26: N | BJ26: Y | BK26: N | BL26: N | BM26: Y | BN26: Y | BO26: 45525 | BP26: Y | BQ26: N | BR26: =IF(COUNTIF(AI26:BM26,"N")+COUNTBLANK(AI26:BM26)=0,"Y","N") | BS26: =IF(AND(BR26="Y",OR(L26="Submitted",L26="Under Review")),"Y",IF(L26="Closed","Y","N")) | BT26: 1 | BU26: =Rule_Flags!Q25 | BV26: =Rule_Flags!P25 | BW26: =IF(Rule_Flags!E25=1,"SITE_CONTROL",IF(Rule_Flags!F25=1,"APPROVALS",IF(Rule_Flags!G25=1,"REPORTS",IF(Rule_Flags!H25=1,"DEFICIENCY",IF(Rule_Flags!I25=1,"UNDERWRITING",IF(Rule_Flags!J25=1,"COMPLIANCE","")))))) | BX26: =IF(BW26="SITE_CONTROL","Site control missing or invalid",IF(BW26="APPROVALS","Required approvals or resolutions incomplete",IF(BW26="REPORTS","Required third-party reports incomplete",IF(BW26="DEFICIENCY","Unresolved deficiency or material deficiency",IF(BW26="UNDERWRITING","Underwriting / feasibility not passed",IF(BW26="COMPLIANCE","Deconcentration, one-mile, LURA, or Chapter 12 issue","Ready under current engine rules")))))) | BY26: =IF(BV26="Determination Notice","Streamlined + DN-ready assumptions satisfied",IF(BV26="Board","Board-required or board-ready assumptions satisfied","")) | BZ26: =IF(AND(BP26="Y",BQ26<>"Y"),"Carryforward project retains queue priority",IF(BQ26="Y","New project enters behind carryforward projects","")) | CA26: =_xludf.RANK.EQ(Rule_Flags!O25,Rule_Flags!$O$3:$O$402,0) | CB26: =IF(OR(BU26="Determination Notice Issued",BU26="Board",BU26="Closed"),"Y","N") | CC26: construction_type mapped from raw 'NC' to 'New Construction' | CD26: Joseph Agumadu | CE26: (214) 342-1400 | CF26: development@sdcus.com | CG26: Teresa Morales | CH26: (512) 475-3344
A27: 2026-02-10 | B27: 2026-02-10 | C27: 21614S | D27: 21614 | E27: Murdeaux Villas | F27: Dallas | G27: Dallas | H27: 3 | I27: 125 S. Murdeaux Lane | J27: 75217 | K27: 45540 | L27: Active | M27: 46058 | O27: 46049 | P27: 46229 | R27: Acq/Rehab | S27: General | T27: 301 | U27: 301 | X27: TDHCA | Y27: TDHCA | Z27: 5000000 | AB27: 3687762 | AF27: N | AG27: Y | AI27: Y | AK27: Y | AL27: Y | AM27: Y | AS27: N | AX27: N | AY27: Y | AZ27: Y | BA27: Y | BB27: Y | BC27: Y | BE27: N | BJ27: Y | BK27: N | BL27: N | BM27: Y | BN27: Y | BO27: 45540 | BP27: Y | BQ27: N | BR27: =IF(COUNTIF(AI27:BM27,"N")+COUNTBLANK(AI27:BM27)=0,"Y","N") | BS27: =IF(AND(BR27="Y",OR(L27="Submitted",L27="Under Review")),"Y",IF(L27="Closed","Y","N")) | BT27: 2 | BU27: =Rule_Flags!Q26 | BV27: =Rule_Flags!P26 | BW27: =IF(Rule_Flags!E26=1,"SITE_CONTROL",IF(Rule_Flags!F26=1,"APPROVALS",IF(Rule_Flags!G26=1,"REPORTS",IF(Rule_Flags!H26=1,"DEFICIENCY",IF(Rule_Flags!I26=1,"UNDERWRITING",IF(Rule_Flags!J26=1,"COMPLIANCE","")))))) | BX27: =IF(BW27="SITE_CONTROL","Site control missing or invalid",IF(BW27="APPROVALS","Required approvals or resolutions incomplete",IF(BW27="REPORTS","Required third-party reports incomplete",IF(BW27="DEFICIENCY","Unresolved deficiency or material deficiency",IF(BW27="UNDERWRITING","Underwriting / feasibility not passed",IF(BW27="COMPLIANCE","Deconcentration, one-mile, LURA, or Chapter 12 issue","Ready under current engine rules")))))) | BY27: =IF(BV27="Determination Notice","Streamlined + DN-ready assumptions satisfied",IF(BV27="Board","Board-required or board-ready assumptions satisfied","")) | BZ27: =IF(AND(BP27="Y",BQ27<>"Y"),"Carryforward project retains queue priority",IF(BQ27="Y","New project enters behind carryforward projects","")) | CA27: =_xludf.RANK.EQ(Rule_Flags!O26,Rule_Flags!$O$3:$O$402,0) | CB27: =IF(OR(BU27="Determination Notice Issued",BU27="Board",BU27="Closed"),"Y","N") | CD27: Ryan Hamilton | CE27: (417) 882-1701 | CF27: ryanhamilton@hamiltoncorporation.com | CG27: Teresa Morales | CH27: (512) 475-3344
A28: 2026-02-10 | B28: 2026-02-10 | C28: 25425 | E28: Bridge at Treeline | F28: Austin | G28: Travis | H28: 7 | I28: 12201 Heatherly Drive | J28: 78747 | K28: 45671 | L28: Withdrawn | M28: 45757 | O28: 45672 | P28: 45852 | R28: New Construction | S28: General | T28: 330 | U28: 330 | X28: Austin Affordable PFC | Y28: Other | Z28: 40000000 | AB28: 2443032 | AF28: N | AG28: Y | AH28: Y | AI28: Y | AK28: Y | AL28: Y | AM28: Y | AS28: N | AX28: N | AY28: Y | AZ28: Y | BA28: Y | BB28: Y | BC28: Y | BE28: N | BJ28: Y | BK28: N | BL28: N | BM28: Y | BN28: Y | BO28: 45671 | BP28: Y | BQ28: N | BR28: =IF(COUNTIF(AI28:BM28,"N")+COUNTBLANK(AI28:BM28)=0,"Y","N") | BS28: =IF(AND(BR28="Y",OR(L28="Submitted",L28="Under Review")),"Y",IF(L28="Closed","Y","N")) | BT28: 29 | BU28: =Rule_Flags!Q27 | BV28: =Rule_Flags!P27 | BW28: =IF(Rule_Flags!E27=1,"SITE_CONTROL",IF(Rule_Flags!F27=1,"APPROVALS",IF(Rule_Flags!G27=1,"REPORTS",IF(Rule_Flags!H27=1,"DEFICIENCY",IF(Rule_Flags!I27=1,"UNDERWRITING",IF(Rule_Flags!J27=1,"COMPLIANCE","")))))) | BX28: =IF(BW28="SITE_CONTROL","Site control missing or invalid",IF(BW28="APPROVALS","Required approvals or resolutions incomplete",IF(BW28="REPORTS","Required third-party reports incomplete",IF(BW28="DEFICIENCY","Unresolved deficiency or material deficiency",IF(BW28="UNDERWRITING","Underwriting / feasibility not passed",IF(BW28="COMPLIANCE","Deconcentration, one-mile, LURA, or Chapter 12 issue","Ready under current engine rules")))))) | BY28: =IF(BV28="Determination Notice","Streamlined + DN-ready assumptions satisfied",IF(BV28="Board","Board-required or board-ready assumptions satisfied","")) | BZ28: =IF(AND(BP28="Y",BQ28<>"Y"),"Carryforward project retains queue priority",IF(BQ28="Y","New project enters behind carryforward projects","")) | CA28: =_xludf.RANK.EQ(Rule_Flags!O27,Rule_Flags!$O$3:$O$402,0) | CB28: =IF(OR(BU28="Determination Notice Issued",BU28="Board",BU28="Closed"),"Y","N") | CC28: construction_type mapped from raw 'NC' to 'New Construction' | CD28: Sam Kumar | CE28: (512) 247-7000 | CF28: SKumar@journeymangroup.com | CG28: Ron Kowal | CH28: 512‐477‐4488
A29: 2026-02-10 | B29: 2026-02-10 | C29: 25431 | D29: 93101 | E29: The Meadows | F29: Garland | G29: Dallas | H29: 3 | I29: 3826 Easton Meadows Drive | J29: 75043 | K29: 45671 | L29: Withdrawn | M29: 45820 | O29: 45672 | P29: 45852 | R29: Acq/Rehab | S29: General | T29: 152 | U29: 152 | X29: Texas Home Collaborative | Y29: Other | Z29: 25000000 | AB29: 1527490 | AF29: N | AG29: Y | AI29: Y | AK29: Y | AL29: Y | AM29: Y | AS29: N | AX29: N | AY29: Y | AZ29: Y | BA29: Y | BB29: Y | BC29: Y | BE29: N | BJ29: Y | BK29: N | BL29: N | BM29: Y | BN29: Y | BO29: 45671 | BP29: Y | BQ29: N | BR29: =IF(COUNTIF(AI29:BM29,"N")+COUNTBLANK(AI29:BM29)=0,"Y","N") | BS29: =IF(AND(BR29="Y",OR(L29="Submitted",L29="Under Review")),"Y",IF(L29="Closed","Y","N")) | BT29: 30 | BU29: =Rule_Flags!Q28 | BV29: =Rule_Flags!P28 | BW29: =IF(Rule_Flags!E28=1,"SITE_CONTROL",IF(Rule_Flags!F28=1,"APPROVALS",IF(Rule_Flags!G28=1,"REPORTS",IF(Rule_Flags!H28=1,"DEFICIENCY",IF(Rule_Flags!I28=1,"UNDERWRITING",IF(Rule_Flags!J28=1,"COMPLIANCE","")))))) | BX29: =IF(BW29="SITE_CONTROL","Site control missing or invalid",IF(BW29="APPROVALS","Required approvals or resolutions incomplete",IF(BW29="REPORTS","Required third-party reports incomplete",IF(BW29="DEFICIENCY","Unresolved deficiency or material deficiency",IF(BW29="UNDERWRITING","Underwriting / feasibility not passed",IF(BW29="COMPLIANCE","Deconcentration, one-mile, LURA, or Chapter 12 issue","Ready under current engine rules")))))) | BY29: =IF(BV29="Determination Notice","Streamlined + DN-ready assumptions satisfied",IF(BV29="Board","Board-required or board-ready assumptions satisfied","")) | BZ29: =IF(AND(BP29="Y",BQ29<>"Y"),"Carryforward project retains queue priority",IF(BQ29="Y","New project enters behind carryforward projects","")) | CA29: =_xludf.RANK.EQ(Rule_Flags!O28,Rule_Flags!$O$3:$O$402,0) | CB29: =IF(OR(BU29="Determination Notice Issued",BU29="Board",BU29="Closed"),"Y","N") | CD29: Brad Fisher | CE29: (913) 787-1676 | CF29: bfisher@aprilhousing.com | CG29: Antonio Williams | CH29: (903) 276-7557
